Workbook
Name RichCapital: '15_DB_SGX_Industry'!$A$406

Sheet 00_Ref
A1: Version: v1.0 | Last updated: 8 Nov 2025
A3: Sheet: 00_ReadMe — Setup and Content Guide
A5: 📌 Purpose
A7: This tab acts as the front cover and navigation guide for the entire workbook. It should be the first sheet users see when opening the file.
A9: 🧩 Section 1: File Metadata
A11: Field | B11: Recommended Entry Example
A12: File Title | B12: SME Valuation Toolkit – Excel Companion
A13: Version | B13: v1.0 (November 2025)
A14: Author Contact | B14: Isaac Wong
A15: Last Updated | B15: =TODAY() -> 46154
A16: Excel Version | B16: Requires Excel 2016 or later
A17: Macros | B17: No macros used — safe for all environments
A19: 🧭 Section 2: Sheet-to-Chapter Mapping
A21: Sheet Name | B21: Corresponds to Chapter
A22: Inputs | B22: Chapter 2 – Normalization
A23: Beta Estimator | B23: Chapter 3 – Estimating Beta
A24: WACC Calculator | B24: Chapter 5 – Weighted Average Cost of Capital
A25: Risk Premiums | B25: Chapters 3, 10–11 – IRP, SCP, CSRP, DLOC, DLOM
A26: DCF Model | B26: Chapter 6 – Integrated Valuation Flow
A27: Income Model - Capitalization | B27: Chapter 7 - Income Based
A28: Market Multiple Model | B28: Chapter 8 - Market Based
A29: Asset Based Model | B29: Chapter 9 - Asset Based
A30: Adjustment Table | B30: Chapters 11 – Post-Valuation Adjustments
A31: Valuation Summary | B31: Chapter 12 – Communicating Findings
A32: Report Template | B32: Chapter 13 – Stakeholder Reporting
... A37: Checklist | B37: Chapter 19
A39: 📘 Section 3: Usage Instructions
A41: How to use this Toolkit: This Excel workbook supports SME valuation using free data and structured logic. Each sheet corresponds to a chapter in the guidebook and automates key steps — from normalization and beta estimation to WACC, DCF modeling, and post-valuation adjustments. Start with the Inputs tab, follow the sheet sequence, and refer to the Checklist for completeness. All formulas are unlocked and editable. No macros are used. This toolkit is designed for transparency, defensibility, and ease of use by CPAs and SME advisors.
A43: Section 4: Quick Start Checklist
A45: Step 1 — Confirm Setup
A47: [ ] Open the workbook in Excel 2016 or later (Microsoft 365 recommended for best compatibility).
A49: [ ] Ensure macros are disabled (none are used in this file).
A51: [ ] Check that the Inputs sheet is visible and accessible.
A53: Step 2 — Enter Key Inputs (01_Inputs)
A55: [ ] Fill in Risk-Free Rate (Rf) (e.g., MAS 10Y yield).
A57: [ ] Enter Equity Risk Premium (ERP) (e.g., NYU Stern data).
A59: [ ] Confirm Corporate Tax Rate (default 17% for Singapore).
A61: [ ] Input Small Company Premium (SCP) and Industry Risk Premium (IRP) if applicable.
... A149: [14_Case Study] → [15_DB_SGX_Industry]

Sheet 00_Dashboard
A1: SME Valuation Dashboard (Sheet: 00_Dashboard)
A3: 🧭 Layout Overview
A5: Section | B5: Purpose | C5: Formatting Tips
A6: A: Key Inputs | B6: Show all named inputs from 01_Inputs | C6: Use light blue header, bold labels
A7: B: Valuation Methods | B7: Show FMV & FV results from each method | C7: Use side-by-side layout, color-coded
A8: C: Final Summary | B8: Show FMV vs FV per share, DLOC/DLOM | C8: Use bold fonts, highlight differences
A9: D: Visual Snapshot | B9: Optional chart (FMV vs FV comparison) | C9: Insert bar chart or heatmap
A11: Section A: Key Inputs
A13: Label | B13: Value | C13: Notes
A14: Risk-Free Rate (Rf) | B14: ='01_Inputs'!E11 -> 2.22 | C14: MAS 10Y yield
A15: Equity Risk Premium | B15: ='01_Inputs'!E12 -> 4.65 | C15: NYU Stern
A16: Corporate Tax Rate | B16: ='01_Inputs'!E13 -> 0.17 | C16: Singapore default 17%
A17: Re-levered Beta | B17: ='01_Inputs'!E14 -> 1.3462115 | C17: From Beta Estimator
A18: WACC | B18: ='01_Inputs'!E18 -> 7.9647855 | C18: From WACC Calculator
A19: Sustainable growth rate/Terminal Growth rate | B19: ='01_Inputs'!E22 -> 0.03 | C19: From Normalization sheet
A20: Shares Outstanding | B20: ='01_Inputs'!E21 -> 500000 | C20: Used for per-share calc
A21: DLOC | B21: ='01_Inputs'!E20 -> 0.26340601 | C21: Discount for lack of control
A22: DLOM | B22: ='01_Inputs'!E19 -> 0.15 | C22: Discount for marketability
A24: Section B: Valuation Methods
A26: Method | B26: FMV (S$) | C26: FV (S$) | D26: Notes | E26: Ratio
A27: Asset-Based | B27: =C27 -> 3683286.9 | C27: ='09_Asset_Based'!E21 -> 3683286.9 | D27: Adjusted net assets | E27: 20
A28: Income-Based (DCF) | B28: =C28 -> 10906059 | C28: ='06_Income_Based DCF'!C34 -> 10906059 | D28: Terminal value applied | E28: 20
A29: Capitalization | B29: =C29 -> 5459562.3 | C29: ='07_Income_Based_Capitalization'!E17 -> 5459562.3 | D29: Based on normalized earnings | E29: 40
A30: Market Multiple | B30: =C30 -> 3427233 | C30: ='08_Market_Multiple'!E33 -> 3427233 | D30: Peer benchmarked | E30: 20
A32: Section C: Final Summary
A34: Metric | B34: FMV (S$) | C34: FV (S$) | D34: Notes
A35: Enterprise Value | B35: =C35 -> 5787140.8 | C35: =(C27*E27%)+(C28*E28%)+(C29*E29%)+(C30*E30%) -> 5787140.8 | D35: From valuation summary
A36: Net Debt | B36: =C36 -> 3825982 | C36: ='05_WACC'!E11 -> 3825982 | D36: Collateralized property loan
A37: Equity Value | B37: =C37 -> 1961158.8 | C37: =C35-C36 -> 1961158.8 | D37: Before discounts
A38: Per Share Value | B38: =C38 -> 3.9223176 | C38: =C37/B20 -> 3.9223176 | D38: Before DLOC/DLOM
A39: Final Value | B39: =B38-(B38*B21*B22) -> 3.7673433 | C39: =C38 -> 3.9223176 | D39: After DLOC/DLOM (FMV only)
A41: 📈 Section D: Visual Snapshot
A43: Insert a clustered bar chart comparing FMV vs FV per method
A45: Use color coding:
A49: FMV = Blue
A51: FV = Green
A53: Label axes:
A57: X-axis = Valuation Method
A59: Y-axis = Value (S$)
A61: Title: “FMV vs FV Comparison by Method”
...

Sheet 000_Steps in screenshot
A1: A | B1: How to draw out public listed companies comparables from your toolkit:
B2: -In this example: Select Industry [Real Estate], SubIndustry [Real Estate Development and Real Estate Services], Profile [Property Development] [Design Specialty] [Building Material-Marble]
B7: 1. Select Worksheet [DB_SGX_Industry]
B11: 2. Select from [DB_SGX_Industry] -(i) "active" in column B (ii) both "m" and "c" in Column C (iii) "Real Estate" in Column D (iv) "Real Estate Development" in Column E and (v) "Property Development" & "Design (vi) "SGD" & "MYR" Specialty" and "Marble"
B28: After checking the dropdown to select items in each column with the steps (i) to (vi):
B46: Fill in the listed companies market and financial data into each columns. The data can be obtained from either SGX or Yahoo Finance.
B68: Next After completed filled in all the data into each companies, move those companies with market capitalization of less than S$300 million in the Mainboard ("m") to the Catalyst ("c") rows:
B86: Calculate the Risk premium for Industry & Small Size Companies:
B120: Compute the Company-Specific Risk Premium (CSRP):
B121: - This figures is obtained from Worksheet [10_CSRP_Scoring]. Use your professional judgement.
B144: Updating the CAPM model in Worksheet [04_CAPM] :
B164: Setting up Market Peers Comparables.
B165: In this case, there are two listed companies of the similar business activities which is Design specialty i.e. Figtree and GRC. Compare their Gross Revenue, EBITDA, Total Assets, FCF, Total Debts and Total Equity, you will find that Figtree is the more relevant for the Market Approach method for valuation.
B208: WACC for DCF Valuation Method. WACC obtained from [05_WACC] and [10_CSRP Scoring]

Sheet 01_Inputs
A1: Disclaimer: This guidebook and its companion toolkit are provided for educational purposes only. They are not intended as financial advice. Users should apply professional judgment and consult relevant standards, regulations, and authorities when performing valuations.
A4: 01_Inputs — Review & Fix Checklist
A6: 🧩 Must-Have Named Inputs
A8: Ensure the following named ranges exist and are clearly labeled in the sheet:
A10: Label in Sheet | B10: Named Range | C10: Suggested Cell | D10: Notes | E10: Inputs
A11: Risk-free rate | B11: Rf | C11: B2 | D11: e.g., 0.025 for 2.5% | E11: =' 04_CAPM'!D4 -> 2.22
A12: Equity risk premium | B12: ERP | C12: B3 | D12: e.g., 0.055 | E12: =' 04_CAPM'!D7 -> 4.65
A13: Corporate tax rate | B13: Singapore Corporate Tax Rate | C13: B4 | D13: Default 0.17 | E13: 0.17
A14: Re-levered Beta | B14: βL=βU×(1+(1−T)*D/E) | D14: Company specific | E14: ='03_Beta_Calculation'!E67 -> 1.3462115
A15: Industry risk premium | B15: IRP | C15: B6 | D15: Optional if not embedded in beta | E15: ='03_Beta_Calculation'!J63 -> 1.6098834
A16: Small-company premium | B16: SCP | C16: B5 | D16: e.g., 0.02 | E16: ='03b_Size Premium Method 15Y'!E27 -> 6.0302554
A17: CSRP | E17: ='10_CSRP_Scoring'!B21 -> 4.4
A18: WACC | E18: ='05_WACC'!E21 -> 7.9647855
A19: DLOM Factor | B19: Floor_DLOM | C19: B7 | D19: Default 0.15 | E19: ='11b_DLOM'!D49 -> 0.15
A20: Control premium (decimal) | B20: Control_Premium | C20: B9 | D20: e.g., 0.30 | E20: ='11a_DLOC'!D32 -> 0.26340601
A21: Shares outstanding | B21: Shares | C21: B10 | D21: e.g., 1,000,000 | E21: ='14_Case Study_Gamma'!B5 -> 500000
A22: Sustainable long term growth rate | B22: g | E22: =' 04_CAPM'!D18 -> 0.03
A24: 💡 Tip: Use Excel’s Name Manager (Ctrl + F3) to confirm these ranges are defined and scoped to the workbook.
A26: ✅ Data Validation Rules
A28: Apply data validation to prevent input errors:
A30: Named Range | B30: Validation Rule | C30: Notes
A31: Rf, ERP, SCP, IRP, TaxRate | B31: Decimal between 0 and 1 | C31: Prevents >100% errors
A32: Floor_DLOM, Cap_DLOM | B32: Decimal between 0 and 1 | C32: Cap must be ≥ Floor
A33: Control_Premium | B33: Decimal between 0 and 1 | C33: e.g., 0.30 for 30%
A34: Shares | B34: Whole number > 0 | C34: No decimals allowed
A36: 📌 Add conditional formatting to flag if Cap_DLOM < Floor_DLOM.
A38: 🔍 Formula Audit: Replace Hard-Coding
A40: Search all other sheets (especially WACC, DCF, Risk Premiums, Adjustment Table) for hard-coded values like:
A42: 0.17 → replace with =Inputs!TaxRate
A44: 0.055 → replace with =Inputs!ERP
A46: 0.02, 0.03, etc. → replace with =Inputs!SCP, =Inputs!IRP, etc.
A48: Use Find & Replace (Ctrl + F) to locate and replace hard-coded values with named ranges.
A50: 🧾 Presentation Tips
A52: Use a clean, two-column layout: Label in Column A, Input Value in Column B.
A54: Add a third column (Column C) for Comments or Default Guidance (e.g., “Default 17% for Singapore corporate tax”).
A56: Freeze top row and left column for usability.
A58: Consider light shading or borders to distinguish input cells.
... A68: [ ] Sheet is clearly labeled and user-friendly.

Sheet 02_Normalization
A3: Reconstructed Income Statements | Q3: Unaudited | R3: Normalised @
A4: The summary of the most recent annual historic Income Statements and the appropriate adjustments are summarised in the table below: | Q4: @ 31 Dec 2026 | R4: 44651
K5: Balance Sheet Items | L5: 2021 | M5: 2022 | N5: 2023 | O5: 2024 | P5: 2025 | Q5: 2026 | R5: @ 31 Mar 2022 | S5: Adjusted
B6: Audited Accounts
A7: Historic Income / Expense Items | B7: 2021 | C7: 2022 | D7: 2023 | E7: 2024 | F7: 2025 | K7: Current Assets
A9: Revenues | B9: 3549913 | C9: 3852126 | D9: 4297121 | E9: 3536194 | F9: 5394455 | K9: Inventories | L9: 0 | M9: 12160 | N9: 12160 | O9: 0 | P9: 0 | R9: 0 | S9: =P9+R9 -> 0
A11: Cost of Goods Sold (COGS) | B11: 2002710 | C11: 2900887 | D11: 3191245 | E11: 2345295 | F11: 2999566 | K11: Trade receivables | L11: =930180+23372 -> 953552 | M11: =717115+63541 -> 780656 | N11: 798757 | O11: 999440 | P11: 1231473 | Q11: =333113+108398 -> 441511 | R11: =394408+5091 -> 399499 | S11: =P11+R11 -> 1630972
A13: Gross Profit | B13: =B9-B11 -> 1547203 | C13: =C9-C11 -> 951239 | D13: =D9-D11 -> 1105876 | E13: =E9-E11 -> 1190899 | F13: =F9-F11 -> 2394889 | K13: Other receivables | L13: 31427 | M13: 40911 | N13: 69573 | O13: 35594 | P13: 328911 | Q13: 12980 | R13: 13143 | S13: =P13+R13 -> 342054
A15: Operating Expenses | B15: =B91 -> 950694 | C15: =C91 -> 1144657 | D15: =D91 -> 1096546 | E15: =E91 -> 1124337 | F15: =F91 -> 1653376 | K15: Amount due from a shareholder | L15: 0 | M15: 208800 | N15: 200000 | O15: 0 | P15: 0 | Q15: 300000 | R15: 342241 | S15: =P15+R15 -> 342241
A17: Operating Income | B17: =B13-B15 -> 596509 | C17: =C13-C15 -> -193418 | D17: =D13-D15 -> 9330 | E17: =E13-E15 -> 66562 | F17: =F13-F15 -> 741513 | K17: Cash and bank balances | L17: 537788 | M17: 387973 | N17: 508107 | O17: 707171 | P17: 253871 | Q17: 1099123 | R17: 732538
A19: Other Income / (expenses) | B19: 91645 | C19: 258581 | D19: 74842 | E19: 51017 | F19: 199652 | K19: Total Current Assets | L19: =SUM(L9:L17) -> 1522767 | M19: =SUM(M9:M17) -> 1430500 | N19: =SUM(N9:N17) -> 1588597 | O19: =SUM(O9:O17) -> 1742205 | P19: =SUM(P9:P17) -> 1814255 | Q19: =SUM(Q9:Q17) -> 1853614 | R19: =SUM(R9:R17) -> 1487421 | S19: =SUM(S9:S17) -> 2315267
A21: Net Pre-Tax Income | B21: =B17+B19 -> 688154 | C21: =C17+C19 -> 65163 | D21: =D17+D19 -> 84172 | E21: =E17+E19 -> 117579 | F21: =F17+F19 -> 941165 | K21: Non-Current Assets
K22: Property, plant and equipment | L22: 301783 | M22: 279139 | N22: 277755 | O22: 270688 | P22: 4859035 | Q22: 4684353 | R22: 4617812 | S22: =P22+R22 -> 9476847
A23: Taxes | B23: 56830 | C23: 0 | D23: 0 | E23: 8706 | F23: 149213 | K23: Investment in subsidairies E(M&S)PL | N23: 0 | O23: 0 | P23: 0 | R23: 150000 | S23: =P23+R23 -> 150000
K24: Available for sale financial assets | N24: 0 | O24: 0 | P24: 0 | S24: =P24+R24 -> 0
A25: Net Income | B25: =B21-B23 -> 631324 | C25: =C21-C23 -> 65163 | D25: =D21-D23 -> 84172 | E25: =E21-E23 -> 108873 | F25: =F21-F23 -> 791952 | K25: Loan to subsidiary | N25: 0 | O25: 0 | P25: 0 | S25: =P25+R25 -> 0
A27: Adjustments to the SCDF: | B27: =SUM(B28:B34)-B56 -> 361896 | C27: =SUM(C28:C34)-C56 -> -172451 | D27: =SUM(D28:D34)-D56 -> 59181 | E27: =SUM(E28:E34)-E56 -> 229772 | F27: =SUM(F28:F34)-F56 -> 331340
A28: Property & Plant written off | B28: 0 | C28: 0 | D28: 0 | E28: 18342 | F28: 17695 | K28: Total Fixed Assets | L28: =SUM(L22:L26) -> 301783 | M28: =SUM(M22:M26) -> 279139 | N28: =SUM(N22:N26) -> 277755 | O28: =SUM(O22:O26) -> 270688 | P28: =SUM(P22:P26) -> 4859035 | Q28: =SUM(Q22:Q26) -> 4684353 | R28: =SUM(R22:R26) -> 4767812 | S28: =SUM(S22:S26) -> 9626847
A29: Bad Debt written off | E29: 6221 | F29: 214000
A30: Depreciation and Amortisation expense | B30: 68957 | C30: 57025 | D30: 64015 | E30: 48775 | F30: 39347 | K30: Less accumulated depreciation
A31: Finance expenses & interest on lease liability | B31: 1985 | C31: 6882 | D31: 2856 | E31: 5201 | F31: 12843 | K31: Plant & Machinery | N31: 0 | O31: 0 | P31: 0 | S31: =P31+R31 -> 0
A32: Government grants | B32: -82546 | C32: -227901 | D32: -40000 | E32: -45232 | F32: -183907 | K32: Renovation | N32: 0 | O32: 0 | P32: 0 | S32: =P32+R32 -> 0
A33: Loss/(Gain) on disposal of plant and equipment | B33: 0 | C33: =-16382+16725 -> 343 | D33: 32310 | E33: -2248 | F33: 31362 | K33: Office equipment | N33: 0 | O33: 0 | P33: 0 | S33: =P33+R33 -> 0
A34: Interest income | B34: 0 | C34: -8800 | D34: 0 | E34: -1287 | F34: 0 | K34: Motor Vehicles | N34: 0 | O34: 0 | P34: 0 | S34: =P34+R34 -> 0
K35: Computer & software | N35: 0 | O35: 0 | P35: 0 | S35: =P35+R35 -> 0
A36: Seller's discretionary cash flow + Dividend paid | B36: =B25+SUM(B28:B34)-B56 -> 993220 | C36: =C25+SUM(C28:C34)-C56 -> -107288 | D36: =D25+SUM(D28:D34)-D56 -> 143353 | E36: =E25+SUM(E28:E34)-E56 -> 338645 | F36: =F25+SUM(F28:F34)-F56 -> 1123292 | N36: =SUM(N31:N35) -> 0
A38: EBIT | B38: =B21+B31+B90 -> 694605 | C38: =C21+C31+C90 -> 80793 | D38: =D21+D31+D90 -> 91492 | E38: =E21+E31+E90 -> 129794 | F38: =F21+F31+F90 -> 967817 | K38: Net Fixed Assets | L38: =L28-L36 -> 301783 | M38: =M28-M36 -> 279139 | N38: =N28-N36 -> 277755 | O38: =O28-O36 -> 270688 | P38: =P28-P36 -> 4859035 | Q38: =Q28-Q36 -> 4684353 | R38: =R28-R36 -> 4767812 | S38: =S28-S36 -> 9626847
A40: EBITDA | B40: =B38+B30 -> 763562 | C40: =C38+C30 -> 137818 | D40: =D38+D30 -> 155507 | E40: =E38+E30 -> 178569 | F40: =F38+F30 -> 1007164 | K40: Total Assets | L40: =L38+L19 -> 1824550 | M40: =M38+M19 -> 1709639 | N40: =N38+N19 -> 1866352 | O40: =O38+O19 -> 2012893 | P40: =P38+P19 -> 6673290 | Q40: =Q38+Q19 -> 6537967 | R40: =R38+R19 -> 6255233 | S40: =S38+S19 -> 11942114
A41: EBITDA less grants (normalised) | B41: =B40+B32 -> 681016 | C41: =C40+C32 -> -90083 | D41: =D40+D32 -> 115507 | E41: =E40+E32 -> 133337 | F41: =F40+F32 -> 823257
A42: Changes in working capital | B42: =SUM(B43:B48) -> -137098 | C42: =SUM(C43:C48) -> -32390 | D42: =SUM(D43:D48) -> -56127 | E42: =SUM(E43:E48) -> 72568 | F42: =SUM(F43:F48) -> -601856 | K42: Current Liabiities
A43: -Inventories | B43: 6576 | C43: -12160 | D43: 0 | E43: 12160 | F43: 0
A44: -Trade receivable | B44: -393392 | C44: 203581 | D44: -110304 | E44: -172925 | F44: -739350 | K44: Contract liabilities | L44: 316979 | M44: 431479 | N44: 456815 | O44: 360834 | P44: 120793 | S44: =P44+R44 -> 120793
A45: -Income tax paid | B45: 0 | C45: -54353 | D45: -4711 | E45: -8706 | F45: -5631 | K45: Trade and other payables | L45: 972708 | M45: 728919 | N45: 698930 | O45: =1397784-360834 -> 1036950 | P45: =1540909-120793 -> 1420116 | Q45: =615246+52321 -> 667567 | R45: =570911+54835 -> 625746 | S45: =P45+R45 -> 2045862
A46: -Other receivables | B46: 0 | C46: 0 | D46: 0 | E46: 0 | F46: 0 | K46: Finance lease payables | L46: 66071 | M46: 9901 | N46: 22287 | O46: 32537 | P46: 11974 | S46: =P46+R46 -> 11974
A47: -Trade and other payables | B47: =370791-121073 -> 249718 | C47: =-243789+74331 -> -169458 | D47: 58888 | E47: 242039 | F47: 143125 | K47: Provision for taxation | L47: 59417 | M47: 5064 | N47: 353 | O47: 353 | P47: 143935 | S47: =P47+R47 -> 143935
B48: 0 | C48: 0 | D48: 0 | E48: 0 | F48: 0 | K48: Term Loans - secured | L48: 0 | M48: 0 | N48: 0 | O48: 0 | P48: 442662 | S48: =P48+R48 -> 442662
A50: Changes in investing & financing | B50: =SUM(B51:B62) -> -663697 | C50: =SUM(C51:C62) -> -238038 | D50: =SUM(D51:D62) -> -7092 | E50: =SUM(E51:E62) -> -66087 | F50: =SUM(F51:F62) -> -1107856
A51: -Amount due from shareholders | B51: 0 | C51: -200000 | D51: 8800 | E51: 200000 | F51: 0 | K51: Total Current Liabiities | L51: =SUM(L44:L48) -> 1415175 | M51: =SUM(M44:M48) -> 1175363 | N51: =SUM(N44:N48) -> 1178385 | O51: =SUM(O44:O48) -> 1430674 | P51: =SUM(P44:P48) -> 2139480 | Q51: =SUM(Q44:Q48) -> 667567 | R51: =SUM(R44:R48) -> 625746 | S51: =SUM(S44:S48) -> 2765226
A52: -Acquisition of property, plant & equipment | B52: -279283 | C52: -16436 | D52: -99441 | E52: -82512 | F52: -4781734
A53: -Proceed from disposal of property, plant & equipment | B53: 0 | C53: 75000 | D53: 101000 | E53: 139898 | F53: 188883 | K53: Non-current liabilities
...

Sheet 03_Beta_Calculation
B1: Adjustments of unlevered beta (UB) due to the Middle East Conflict which may have a negative effect on the Singapore Real Estate Industry:
B2: Factors to adjust as of (April 2026):
B3: 1. Cost Factor (Increase Risk)
B4: 2. Capital Flow Factor (Decrease Risk): Heightened tensions can cause a flight to safety, where wealthy individuals and investors move capital into Singapore, increasing property demand
B5: 3. Valuation Factor (Mixed): A prolonged conflict might cause higher inflation, raising long-term borrowing costs, which is negative for S-REITs
B6: 4. Suggested Adjustment Magnitude:
B7: 4a. If the REIT has high exposure to Industrial/logistics assets: -Increase beta by +0.05 to +0.10 to account for supply chain disruption risks, despite potential logistical benefits.
B8: 4b. If the REIT is a prime office/residential "Safe Haven" play: The beta might actually remain stable or slightly decrease due to capital inflows, but the higher interest rate environment suggests a modest increase of +0.05 to account for valuation volatility.
B9: Summary Recommendation: Instead of a straight addition to the final levered beta, increase the Unlevered Beta of the comparable peer set by a factor reflecting your specific risk scenario (e.g. 5-10%) higher for a moderate risk scenario then re-lever it.
A10: A | B10: Calculations of Industry Risk in a Buildup Model
C12: Total Mkt Cap $ | D12: LB (obtained from SGX) | E12: UB = LB /(1+ (1-T)* (D/E)) | F12: D %age of debts | G12: E %age of equity | H12: Total debt | I12: Total Equity | J12: Total Equity Total Debts | K12: P/E ratio | L12: Dividend yield | M12: Sh price on 10 May 2022 | N12: Sh price on 31 Decc 2021 | O12: Percentage +ve drop/-ve increase | P12: Gross Revenue ($million) | Q12: EBITDA | R12: Total Assets | S12: Free Cash Flow (FCF) | T12: Price/Gross Revenue | U12: Price/EBITDA | V12: Price/Total Assests | W12: Price/FCF
A13: 1 | B13: ='16_DB-SGX_Loading'!B10 -> COSCO SHP SG | C13: ='16_DB-SGX_Loading'!C10 -> 510.548 | D13: ='16_DB-SGX_Loading'!D10 -> 0.71 | E13: =D13/(1+(1-0.17)*(F13/G13)) -> 0.64578105 | F13: =H13/J13% -> 10.699284 | G13: =I13/J13% -> 89.300716 | H13: ='16_DB-SGX_Loading'!E10 -> 93.583 | I13: ='16_DB-SGX_Loading'!F10 -> 781.083 | J13: =H13+I13 -> 874.666 | K13: ='16_DB-SGX_Loading'!H10 -> 0 | L13: ='16_DB-SGX_Loading'!I10 -> 0.78 | M13: ='16_DB-SGX_Loading'!J10 -> 0.114 | N13: ='16_DB-SGX_Loading'!K10 -> 0.121 | O13: =(M13-N13)/N13*100 -> -5.785124 | P13: ='16_DB-SGX_Loading'!M10 -> 193.999 | Q13: ='16_DB-SGX_Loading'!N10 -> 61.285 | R13: ='16_DB-SGX_Loading'!O10 -> 980.308 | S13: ='16_DB-SGX_Loading'!P10 -> 33.245 | T13: =C13/P13 -> 2.6317043 | U13: =C13/Q13 -> 8.3307171 | V13: =C13/R13 -> 0.52080367 | W13: =C13/S13 -> 15.357136
A14: 2 | B14: ='16_DB-SGX_Loading'!B11 -> SATS | C14: ='16_DB-SGX_Loading'!C11 -> 5321 | D14: ='16_DB-SGX_Loading'!D11 -> 0.52 | E14: =D14/(1+(1-0.17)*(F14/G14)) -> 0.33495355 | F14: =H14/J14% -> 39.961838 | G14: =I14/J14% -> 60.038162 | H14: ='16_DB-SGX_Loading'!E11 -> 1843 | I14: ='16_DB-SGX_Loading'!F11 -> 2768.9 | J14: =H14+I14 -> 4611.9 | K14: ='16_DB-SGX_Loading'!H11 -> 19.89 | L14: ='16_DB-SGX_Loading'!I11 -> 1.54 | M14: ='16_DB-SGX_Loading'!J11 -> 3.58 | N14: ='16_DB-SGX_Loading'!K11 -> 3.81 | O14: =(M14-N14)/N14*100 -> -6.0367454 | P14: ='16_DB-SGX_Loading'!M11 -> 5821 | Q14: ='16_DB-SGX_Loading'!N11 -> 1166 | R14: ='16_DB-SGX_Loading'!O11 -> 8882 | S14: ='16_DB-SGX_Loading'!P11 -> 669.4 | T14: =C14/P14 -> 0.91410411 | U14: =C14/Q14 -> 4.5634648 | V14: =C14/R14 -> 0.59907678 | W14: =C14/S14 -> 7.9489095
A15: 3 | B15: ='16_DB-SGX_Loading'!B12 -> SIA | C15: ='16_DB-SGX_Loading'!C12 -> 20973 | D15: ='16_DB-SGX_Loading'!D12 -> 0.5 | E15: =D15/(1+(1-0.17)*(F15/G15)) -> 0.29993801 | F15: =H15/J15% -> 44.556191 | G15: =I15/J15% -> 55.443809 | H15: ='16_DB-SGX_Loading'!E12 -> 12914.3 | I15: ='16_DB-SGX_Loading'!F12 -> 16070 | J15: =H15+I15 -> 28984.3 | K15: ='16_DB-SGX_Loading'!H12 -> 17.5 | L15: ='16_DB-SGX_Loading'!I12 -> 5.26 | M15: ='16_DB-SGX_Loading'!J12 -> 6.65 | N15: ='16_DB-SGX_Loading'!K12 -> 6.4 | O15: =(M15-N15)/N15*100 -> 3.90625 | P15: ='16_DB-SGX_Loading'!M12 -> 19539.8 | Q15: ='16_DB-SGX_Loading'!N12 -> 5711.9 | R15: ='16_DB-SGX_Loading'!O12 -> 43086.8 | S15: ='16_DB-SGX_Loading'!P12 -> 2834 | T15: =C15/P15 -> 1.0733477 | U15: =C15/Q15 -> 3.671808 | V15: =C15/R15 -> 0.48676161 | W15: =C15/S15 -> 7.400494
A16: 4 | B16: ='16_DB-SGX_Loading'!B13 -> SIA Engineering | C16: ='16_DB-SGX_Loading'!C13 -> 3651 | D16: ='16_DB-SGX_Loading'!D13 -> 0.32 | E16: =D16/(1+(1-0.17)*(F16/G16)) -> 0.30751392 | F16: =H16/J16% -> 4.6638129 | G16: =I16/J16% -> 95.336187 | H16: ='16_DB-SGX_Loading'!E13 -> 85.199 | I16: ='16_DB-SGX_Loading'!F13 -> 1741.611 | J16: =H16+I16 -> 1826.81 | K16: ='16_DB-SGX_Loading'!H13 -> 23.29 | L16: ='16_DB-SGX_Loading'!I13 -> 2.91 | M16: ='16_DB-SGX_Loading'!J13 -> 3.26 | N16: ='16_DB-SGX_Loading'!K13 -> 3.6 | O16: =(M16-N16)/N16*100 -> -9.4444444 | P16: ='16_DB-SGX_Loading'!M13 -> 1245 | Q16: ='16_DB-SGX_Loading'!N13 -> 214.881 | R16: ='16_DB-SGX_Loading'!O13 -> 2141.393 | S16: ='16_DB-SGX_Loading'!P13 -> 102.603 | T16: =C16/P16 -> 2.9325301 | U16: =C16/Q16 -> 16.9908 | V16: =C16/R16 -> 1.7049649 | W16: =C16/S16 -> 35.583755
A17: 5 | B17: ='16_DB-SGX_Loading'!B14 -> SingPost | C17: ='16_DB-SGX_Loading'!C14 -> 776.687 | D17: ='16_DB-SGX_Loading'!D14 -> 0.21 | E17: =D17/(1+(1-0.17)*(F17/G17)) -> 0.17629808 | F17: =H17/J17% -> 18.720237 | G17: =I17/J17% -> 81.279763 | H17: ='16_DB-SGX_Loading'!E14 -> 370.232 | I17: ='16_DB-SGX_Loading'!F14 -> 1607.478 | J17: =H17+I17 -> 1977.71 | K17: ='16_DB-SGX_Loading'!H14 -> 3.14 | L17: ='16_DB-SGX_Loading'!I14 -> 1.22 | M17: ='16_DB-SGX_Loading'!J14 -> 0.345 | N17: ='16_DB-SGX_Loading'!K14 -> 0.405 | O17: =(M17-N17)/N17*100 -> -14.814815 | P17: ='16_DB-SGX_Loading'!M14 -> 813.704 | Q17: ='16_DB-SGX_Loading'!N14 -> 387.25 | R17: ='16_DB-SGX_Loading'!O14 -> 2390.424 | S17: ='16_DB-SGX_Loading'!P14 -> 26.671 | T17: =C17/P17 -> 0.95450803 | U17: =C17/Q17 -> 2.0056475 | V17: =C17/R17 -> 0.324916 | W17: =C17/S17 -> 29.12103
A18: 6 | B18: ='16_DB-SGX_Loading'!B15 -> Wing Tai | C18: ='16_DB-SGX_Loading'!C15 -> 1222 | D18: ='16_DB-SGX_Loading'!D15 -> 0.23 | E18: =D18/(1+(1-0.17)*(F18/G18)) -> 0.16972396 | F18: =H18/J18% -> 29.966174 | G18: =I18/J18% -> 70.033826 | H18: ='16_DB-SGX_Loading'!E15 -> 1242.121 | I18: ='16_DB-SGX_Loading'!F15 -> 2902.956 | J18: =H18+I18 -> 4145.077 | K18: ='16_DB-SGX_Loading'!H15 -> 0 | L18: ='16_DB-SGX_Loading'!I15 -> 1.88 | M18: ='16_DB-SGX_Loading'!J15 -> 1.6 | N18: ='16_DB-SGX_Loading'!K15 -> 1.42 | O18: =(M18-N18)/N18*100 -> 12.676056 | P18: ='16_DB-SGX_Loading'!M15 -> 230.206 | Q18: ='16_DB-SGX_Loading'!N15 -> -4.157 | R18: ='16_DB-SGX_Loading'!O15 -> 4275.552 | S18: ='16_DB-SGX_Loading'!P15 -> -447.444 | T18: =C18/P18 -> 5.3082891 | U18: =C18/Q18 -> -293.96199 | V18: =C18/R18 -> 0.28581105 | W18: =C18/S18 -> -2.731068
A19: 7 | B19: ='16_DB-SGX_Loading'!B16 -> CapitaLandInvest | C19: ='16_DB-SGX_Loading'!C16 -> 13679 | D19: ='16_DB-SGX_Loading'!D16 -> 0.61 | E19: =D19/(1+(1-0.17)*(F19/G19)) -> 0.40149196 | F19: =H19/J19% -> 38.488129 | G19: =I19/J19% -> 61.511871 | H19: ='16_DB-SGX_Loading'!E16 -> 8462 | I19: ='16_DB-SGX_Loading'!F16 -> 13524 | J19: =H19+I19 -> 21986 | K19: ='16_DB-SGX_Loading'!H16 -> 91.33 | L19: ='16_DB-SGX_Loading'!I16 -> 4.38 | M19: ='16_DB-SGX_Loading'!J16 -> 2.74 | N19: ='16_DB-SGX_Loading'!K16 -> 2.71 | O19: =(M19-N19)/N19*100 -> 1.1070111 | P19: ='16_DB-SGX_Loading'!M16 -> 2133 | Q19: ='16_DB-SGX_Loading'!N16 -> 735 | R19: ='16_DB-SGX_Loading'!O16 -> 24211 | S19: ='16_DB-SGX_Loading'!P16 -> 479 | T19: =C19/P19 -> 6.4130333 | U19: =C19/Q19 -> 18.610884 | V19: =C19/R19 -> 0.56499112 | W19: =C19/S19 -> 28.557411
A20: 8 | B20: ='16_DB-SGX_Loading'!B17 -> ComfortDelGro | C20: ='16_DB-SGX_Loading'!C17 -> 3120 | D20: ='16_DB-SGX_Loading'!D17 -> 0.24 | E20: =D20/(1+(1-0.17)*(F20/G20)) -> 0.15923447 | F20: =H20/J20% -> 37.930532 | G20: =I20/J20% -> 62.069468 | H20: ='16_DB-SGX_Loading'!E17 -> 1821.5 | I20: ='16_DB-SGX_Loading'!F17 -> 2980.7 | J20: =H20+I20 -> 4802.2 | K20: ='16_DB-SGX_Loading'!H17 -> 13.09 | L20: ='16_DB-SGX_Loading'!I17 -> 5.9 | M20: ='16_DB-SGX_Loading'!J17 -> 1.44 | N20: ='16_DB-SGX_Loading'!K17 -> 1.48 | O20: =(M20-N20)/N20*100 -> -2.7027027 | P20: ='16_DB-SGX_Loading'!M17 -> 5058 | Q20: ='16_DB-SGX_Loading'!N17 -> 793.8 | R20: ='16_DB-SGX_Loading'!O17 -> 6138.9 | S20: ='16_DB-SGX_Loading'!P17 -> -136.5 | T20: =C20/P20 -> 0.6168446 | U20: =C20/Q20 -> 3.9304611 | V20: =C20/R20 -> 0.50823437 | W20: =C20/S20 -> -22.857143
A21: 9 | B21: ='16_DB-SGX_Loading'!B18 -> Frasers Property | C21: ='16_DB-SGX_Loading'!C18 -> 3808 | D21: ='16_DB-SGX_Loading'!D18 -> 0.33 | E21: =D21/(1+(1-0.17)*(F21/G21)) -> 0.17398972 | F21: =H21/J21% -> 51.930422 | G21: =I21/J21% -> 48.069578 | H21: ='16_DB-SGX_Loading'!E18 -> 18525.843 | I21: ='16_DB-SGX_Loading'!F18 -> 17148.512 | J21: =H21+I21 -> 35674.355 | K21: ='16_DB-SGX_Loading'!H18 -> 16.17 | L21: ='16_DB-SGX_Loading'!I18 -> 4.64 | M21: ='16_DB-SGX_Loading'!J18 -> 0.97 | N21: ='16_DB-SGX_Loading'!K18 -> 1.13 | O21: =(M21-N21)/N21*100 -> -14.159292 | P21: ='16_DB-SGX_Loading'!M18 -> 3403.519 | Q21: ='16_DB-SGX_Loading'!N18 -> 1322.534 | R21: ='16_DB-SGX_Loading'!O18 -> 39747.618 | S21: ='16_DB-SGX_Loading'!P18 -> 981.788 | T21: =C21/P21 -> 1.118842 | U21: =C21/Q21 -> 2.8793211 | V21: =C21/R21 -> 0.095804483 | W21: =C21/S21 -> 3.8786378
B23: Total: | D23: =SUM(D13:D21) -> 3.67 | E23: =SUM(E13:E21) -> 2.6689247 | F23: =AVERAGE(H13:H21)/AVERAGE(I13:I21) -> 0.76199236 | G23: Average D/Average L
B24: Average: | D24: =AVERAGE(D13:D21) -> 0.40777778 | E24: =AVERAGE(E13:E21) -> 0.29654719 | F24: =E24*(1+(1-E70)*F23) -> 0.48409955 | G24: rel-levered beta using the industry component stocks D/L
A25: 4 | B25: Premium for Industry specific: | E25: =D29 -> -2.3989371
B26: *Where T is the corporate tax rate of 17%
B27: Re-levered beta of average 9 comparables | C27: Ri | D27: =F24 -> 0.48409955
C28: ERP | D28: =' 04_CAPM'!D7 -> 4.65
B29: IRPί = (Rί X ERP) - ERP | C29: IRPi | D29: =(D27*D28)-D28 -> -2.3989371
B30: IRPί = (1.234 X 4.65) - 4.65 = 5.7381 -4.65 = 1.0881
B32: assuming Rί = 1.234 re-levered beta for the Event Management industry
A34: where:
A35: IRPί = the expected industry risk premium for industry ί, or the amount by which investors expect the future return of the industry to exceed that of the market as a whole;
A36: Ri = the risk index (full information beta) for the industry ί; and
A37: ERP = the expected equity risk premium
A42: B | B42: Calculations of Unlevered beta for small cap stocks
B43: Data/Information from SGX website
C44: Total Mkt Cap $ million | D44: LB | E44: UB = LB / (1+ (1-T)* (D/E)) | F44: D %age of debts [Total Debt / (Total Equity + Total Debt)] | G44: E %age of equity [Total Equity / (Total Equity + Total Debt)] | H44: Total debt | I44: Total Equity | J44: Total Equity + Total Debts | K44: P/E ratio | L44: Dividend yield | M44: Sh price on 30 Apr 2025 | N44: Sh price on 31 Dec 2024 | O44: Percentage +ve drop/-ve increase | P44: Gross Revenue ($million) | Q44: EBITDA | R44: Total Assets | S44: Free Cash Flow (FCF) | T44: Price/Gross Revenue | U44: Price/EBITDA | V44: Price/Total Assests | W44: Price/FCF | X44: Stk code | Y44: Currency
A45: 1 | B45: ='16_DB-SGX_Loading'!B22 -> Audience | C45: ='16_DB-SGX_Loading'!C22 -> 60.492 | D45: ='16_DB-SGX_Loading'!D22 -> 0.08 | E45: =D45/(1+(1-$D$76)*(F45/G45)) -> 0.079920179 | F45: =H45/J45% -> 0.12018715 | G45: =I45/J45% -> 99.879813 | H45: ='16_DB-SGX_Loading'!E22 -> 0.028 | I45: ='16_DB-SGX_Loading'!F22 -> 23.269 | J45: =H45+I45 -> 23.297 | K45: ='16_DB-SGX_Loading'!H22 -> 13 | L45: ='16_DB-SGX_Loading'!I22 -> 5.77 | M45: ='16_DB-SGX_Loading'!J22 -> 0.26 | N45: ='16_DB-SGX_Loading'!K22 -> 0.26 | O45: =(N45-M45)/N45*100 -> 0 | P45: ='16_DB-SGX_Loading'!M22 -> 15.956 | Q45: ='16_DB-SGX_Loading'!N22 -> 5.788 | R45: ='16_DB-SGX_Loading'!O22 -> 26.015 | S45: ='16_DB-SGX_Loading'!P22 -> 4.436 | T45: ='16_DB-SGX_Loading'!Q22 -> 3.7911757 | U45: ='16_DB-SGX_Loading'!R22 -> 10.451279 | V45: ='16_DB-SGX_Loading'!S22 -> 2.3252739 | W45: ='16_DB-SGX_Loading'!T22 -> 13.63661 | X45: 1AZ
A46: 2 | B46: ='16_DB-SGX_Loading'!B23 -> Dezign Format | C46: ='16_DB-SGX_Loading'!C23 -> 38 | D46: ='16_DB-SGX_Loading'!D23 -> 1 | E46: =D46/(1+(1-$D$76)*(F46/G46)) -> 0.84807461 | F46: =H46/J46% -> 17.751875 | G46: =I46/J46% -> 82.248125 | H46: ='16_DB-SGX_Loading'!E23 -> 2.391 | I46: ='16_DB-SGX_Loading'!F23 -> 11.078 | J46: =H46+I46 -> 13.469 | K46: ='16_DB-SGX_Loading'!H23 -> 19 | L46: ='16_DB-SGX_Loading'!I23 -> 0 | M46: ='16_DB-SGX_Loading'!J23 -> 0.19 | N46: ='16_DB-SGX_Loading'!K23 -> 0.23 | O46: =(N46-M46)/N46*100 -> 17.391304 | P46: ='16_DB-SGX_Loading'!M23 -> 33.104 | Q46: ='16_DB-SGX_Loading'!N23 -> 3.03 | R46: ='16_DB-SGX_Loading'!O23 -> 24.951 | S46: ='16_DB-SGX_Loading'!P23 -> -6.511 | T46: ='16_DB-SGX_Loading'!Q23 -> 1.1478975 | U46: ='16_DB-SGX_Loading'!R23 -> 12.541254 | V46: ='16_DB-SGX_Loading'!S23 -> 1.5229851 | W46: ='16_DB-SGX_Loading'!T23 -> -5.8362771 | X46: UZF
A47: 3 | B47: ='16_DB-SGX_Loading'!B24 -> GKE | C47: ='16_DB-SGX_Loading'!C24 -> 64.395 | D47: ='16_DB-SGX_Loading'!D24 -> 0.28 | E47: =D47/(1+(1-$D$76)*(F47/G47)) -> 0.1943974 | F47: =H47/J47% -> 34.663595 | G47: =I47/J47% -> 65.336405 | H47: ='16_DB-SGX_Loading'!E24 -> 53.123 | I47: ='16_DB-SGX_Loading'!F24 -> 100.13 | J47: =H47+I47 -> 153.253 | K47: ='16_DB-SGX_Loading'!H24 -> 7.5 | L47: ='16_DB-SGX_Loading'!I24 -> 5.33 | M47: ='16_DB-SGX_Loading'!J24 -> 0.075 | N47: ='16_DB-SGX_Loading'!K24 -> 0.095 | O47: =(N47-M47)/N47*100 -> 21.052632 | P47: ='16_DB-SGX_Loading'!M24 -> 126.519 | Q47: ='16_DB-SGX_Loading'!N24 -> 29.927 | R47: ='16_DB-SGX_Loading'!O24 -> 184.24 | S47: ='16_DB-SGX_Loading'!P24 -> 14.761 | T47: ='16_DB-SGX_Loading'!Q24 -> 0.50897494 | U47: ='16_DB-SGX_Loading'!R24 -> 2.1517359 | V47: ='16_DB-SGX_Loading'!S24 -> 0.34951693 | W47: ='16_DB-SGX_Loading'!T24 -> 4.3625093 | X47: 595 | Y47: JPY
A48: 4 | B48: ='16_DB-SGX_Loading'!B25 -> Hiap Tong | C48: ='16_DB-SGX_Loading'!C25 -> 35.545 | D48: ='16_DB-SGX_Loading'!D25 -> -0.04 | E48: =D48/(1+(1-$D$76)*(F48/G48)) -> -0.027828632 | F48: =H48/J48% -> 34.509974 | G48: =I48/J48% -> 65.490026 | H48: ='16_DB-SGX_Loading'!E25 -> 52.646 | I48: ='16_DB-SGX_Loading'!F25 -> 99.907 | J48: =H48+I48 -> 152.553 | K48: ='16_DB-SGX_Loading'!H25 -> 11.2 | L48: ='16_DB-SGX_Loading'!I25 -> 0.89 | M48: ='16_DB-SGX_Loading'!J25 -> 0.112 | N48: ='16_DB-SGX_Loading'!K25 -> 0.096 | O48: =(N48-M48)/N48*100 -> -16.666667 | P48: ='16_DB-SGX_Loading'!M25 -> 91.916 | Q48: ='16_DB-SGX_Loading'!N25 -> 23.985 | R48: ='16_DB-SGX_Loading'!O25 -> 182.026 | S48: ='16_DB-SGX_Loading'!P25 -> 19.872 | T48: ='16_DB-SGX_Loading'!Q25 -> 0.38671178 | U48: ='16_DB-SGX_Loading'!R25 -> 1.4819679 | V48: ='16_DB-SGX_Loading'!S25 -> 0.1952743 | W48: ='16_DB-SGX_Loading'!T25 -> 1.7886977 | X48: 5PO
...

Sheet 03i_Beta_Calculation
A1: 1 | B1: Calculations of Industry Risk in a Buildup Model
A3: a | B3: Mid and Large Cap Stock
B4: Data/Information from SGX or Yahoo Finance website
C5: Total Mkt Cap $ million | D5: LB | E5: UB = LB / (1+ (1-T)* (D/E)) | F5: D %age of debts [Total Debt / (Total Equity + Total Debt)] | G5: E %age of equity [Total Equity / (Total Equity + Total Debt)] | H5: Total debt | I5: Total Equity | J5: Total Equity + Total Debts | K5: P/E ratio | L5: Dividend yield | M5: Sh price on 3 Apr 2026 | N5: Sh price on 31 Dec 2025 | O5: Percentage +ve drop/-ve increase | P5: Gross Revenue ($million) | Q5: EBITDA | R5: Total Assets | S5: Free Cash Flow (FCF) | T5: Price/Gross Revenue | U5: Price/EBITDA | V5: Price/Total Assests | W5: Price/FCF | X5: Stk code | Y5: Currency
A6: 1 | B6: ='16_DB-SGX_Loading'!B10 -> COSCO SHP SG | C6: ='16_DB-SGX_Loading'!C10 -> 510.548 | D6: ='16_DB-SGX_Loading'!D10 -> 0.71 | E6: =D6/(1+(1-0.17)*(F6/G6)) -> 0.64578105 | F6: =H6/J6% -> 10.699284 | G6: =I6/J6% -> 89.300716 | H6: ='16_DB-SGX_Loading'!E10 -> 93.583 | I6: ='16_DB-SGX_Loading'!F10 -> 781.083 | J6: =H6+I6 -> 874.666 | K6: ='16_DB-SGX_Loading'!H10 -> 0 | L6: ='16_DB-SGX_Loading'!I10 -> 0.78 | M6: ='16_DB-SGX_Loading'!J10 -> 0.114 | N6: ='16_DB-SGX_Loading'!K10 -> 0.121 | O6: =(M6-N6)/N6*100 -> -5.785124 | P6: ='16_DB-SGX_Loading'!M10 -> 193.999 | Q6: ='16_DB-SGX_Loading'!N10 -> 61.285 | R6: ='16_DB-SGX_Loading'!O10 -> 980.308 | S6: ='16_DB-SGX_Loading'!P10 -> 33.245 | T6: =C6/P6 -> 2.6317043 | U6: =C6/Q6 -> 8.3307171 | V6: =C6/R6 -> 0.52080367 | W6: =C6/S6 -> 15.357136 | X6: ='16_DB-SGX_Loading'!W10 -> F83
A7: 2 | B7: ='16_DB-SGX_Loading'!B11 -> SATS | C7: ='16_DB-SGX_Loading'!C11 -> 5321 | D7: ='16_DB-SGX_Loading'!D11 -> 0.52 | E7: =D7/(1+(1-0.17)*(F7/G7)) -> 0.33495355 | F7: =H7/J7% -> 39.961838 | G7: =I7/J7% -> 60.038162 | H7: ='16_DB-SGX_Loading'!E11 -> 1843 | I7: ='16_DB-SGX_Loading'!F11 -> 2768.9 | J7: =H7+I7 -> 4611.9 | K7: ='16_DB-SGX_Loading'!H11 -> 19.89 | L7: ='16_DB-SGX_Loading'!I11 -> 1.54 | M7: ='16_DB-SGX_Loading'!J11 -> 3.58 | N7: ='16_DB-SGX_Loading'!K11 -> 3.81 | O7: =(M7-N7)/N7*100 -> -6.0367454 | P7: ='16_DB-SGX_Loading'!M11 -> 5821 | Q7: ='16_DB-SGX_Loading'!N11 -> 1166 | R7: ='16_DB-SGX_Loading'!O11 -> 8882 | S7: ='16_DB-SGX_Loading'!P11 -> 669.4 | T7: =C7/P7 -> 0.91410411 | U7: =C7/Q7 -> 4.5634648 | V7: =C7/R7 -> 0.59907678 | W7: =C7/S7 -> 7.9489095 | X7: ='16_DB-SGX_Loading'!W11 -> S58
A8: 3 | B8: ='16_DB-SGX_Loading'!B12 -> SIA | C8: ='16_DB-SGX_Loading'!C12 -> 20973 | D8: ='16_DB-SGX_Loading'!D12 -> 0.5 | E8: =D8/(1+(1-0.17)*(F8/G8)) -> 0.29993801 | F8: =H8/J8% -> 44.556191 | G8: =I8/J8% -> 55.443809 | H8: ='16_DB-SGX_Loading'!E12 -> 12914.3 | I8: ='16_DB-SGX_Loading'!F12 -> 16070 | J8: =H8+I8 -> 28984.3 | K8: ='16_DB-SGX_Loading'!H12 -> 17.5 | L8: ='16_DB-SGX_Loading'!I12 -> 5.26 | M8: ='16_DB-SGX_Loading'!J12 -> 6.65 | N8: ='16_DB-SGX_Loading'!K12 -> 6.4 | O8: =(M8-N8)/N8*100 -> 3.90625 | P8: ='16_DB-SGX_Loading'!M12 -> 19539.8 | Q8: ='16_DB-SGX_Loading'!N12 -> 5711.9 | R8: ='16_DB-SGX_Loading'!O12 -> 43086.8 | S8: ='16_DB-SGX_Loading'!P12 -> 2834 | T8: =C8/P8 -> 1.0733477 | U8: =C8/Q8 -> 3.671808 | V8: =C8/R8 -> 0.48676161 | W8: =C8/S8 -> 7.400494 | X8: ='16_DB-SGX_Loading'!W12 -> C6L
A9: 4 | B9: ='16_DB-SGX_Loading'!B13 -> SIA Engineering | C9: ='16_DB-SGX_Loading'!C13 -> 3651 | D9: ='16_DB-SGX_Loading'!D13 -> 0.32 | E9: =D9/(1+(1-0.17)*(F9/G9)) -> 0.30751392 | F9: =H9/J9% -> 4.6638129 | G9: =I9/J9% -> 95.336187 | H9: ='16_DB-SGX_Loading'!E13 -> 85.199 | I9: ='16_DB-SGX_Loading'!F13 -> 1741.611 | J9: =H9+I9 -> 1826.81 | K9: ='16_DB-SGX_Loading'!H13 -> 23.29 | L9: ='16_DB-SGX_Loading'!I13 -> 2.91 | M9: ='16_DB-SGX_Loading'!J13 -> 3.26 | N9: ='16_DB-SGX_Loading'!K13 -> 3.6 | O9: =(M9-N9)/N9*100 -> -9.4444444 | P9: ='16_DB-SGX_Loading'!M13 -> 1245 | Q9: ='16_DB-SGX_Loading'!N13 -> 214.881 | R9: ='16_DB-SGX_Loading'!O13 -> 2141.393 | S9: ='16_DB-SGX_Loading'!P13 -> 102.603 | T9: =C9/P9 -> 2.9325301 | U9: =C9/Q9 -> 16.9908 | V9: =C9/R9 -> 1.7049649 | W9: =C9/S9 -> 35.583755 | X9: ='16_DB-SGX_Loading'!W13 -> S59
A10: 5 | B10: ='16_DB-SGX_Loading'!B14 -> SingPost | C10: ='16_DB-SGX_Loading'!C14 -> 776.687 | D10: ='16_DB-SGX_Loading'!D14 -> 0.21 | E10: =D10/(1+(1-0.17)*(F10/G10)) -> 0.17629808 | F10: =H10/J10% -> 18.720237 | G10: =I10/J10% -> 81.279763 | H10: ='16_DB-SGX_Loading'!E14 -> 370.232 | I10: ='16_DB-SGX_Loading'!F14 -> 1607.478 | J10: =H10+I10 -> 1977.71 | K10: ='16_DB-SGX_Loading'!H14 -> 3.14 | L10: ='16_DB-SGX_Loading'!I14 -> 1.22 | M10: ='16_DB-SGX_Loading'!J14 -> 0.345 | N10: ='16_DB-SGX_Loading'!K14 -> 0.405 | O10: =(M10-N10)/N10*100 -> -14.814815 | P10: ='16_DB-SGX_Loading'!M14 -> 813.704 | Q10: ='16_DB-SGX_Loading'!N14 -> 387.25 | R10: ='16_DB-SGX_Loading'!O14 -> 2390.424 | S10: ='16_DB-SGX_Loading'!P14 -> 26.671 | T10: =C10/P10 -> 0.95450803 | U10: =C10/Q10 -> 2.0056475 | V10: =C10/R10 -> 0.324916 | W10: =C10/S10 -> 29.12103 | X10: ='16_DB-SGX_Loading'!W14 -> S08
A11: 6 | B11: ='16_DB-SGX_Loading'!B15 -> Wing Tai | C11: ='16_DB-SGX_Loading'!C15 -> 1222 | D11: ='16_DB-SGX_Loading'!D15 -> 0.23 | E11: =D11/(1+(1-0.17)*(F11/G11)) -> 0.16972396 | F11: =H11/J11% -> 29.966174 | G11: =I11/J11% -> 70.033826 | H11: ='16_DB-SGX_Loading'!E15 -> 1242.121 | I11: ='16_DB-SGX_Loading'!F15 -> 2902.956 | J11: =H11+I11 -> 4145.077 | K11: ='16_DB-SGX_Loading'!H15 -> 0 | L11: ='16_DB-SGX_Loading'!I15 -> 1.88 | M11: ='16_DB-SGX_Loading'!J15 -> 1.6 | N11: ='16_DB-SGX_Loading'!K15 -> 1.42 | O11: =(M11-N11)/N11*100 -> 12.676056 | P11: ='16_DB-SGX_Loading'!M15 -> 230.206 | Q11: ='16_DB-SGX_Loading'!N15 -> -4.157 | R11: ='16_DB-SGX_Loading'!O15 -> 4275.552 | S11: ='16_DB-SGX_Loading'!P15 -> -447.444 | T11: =C11/P11 -> 5.3082891 | U11: =C11/Q11 -> -293.96199 | V11: =C11/R11 -> 0.28581105 | W11: =C11/S11 -> -2.731068 | X11: ='16_DB-SGX_Loading'!W15 -> W05
A12: 7 | B12: ='16_DB-SGX_Loading'!B16 -> CapitaLandInvest | C12: ='16_DB-SGX_Loading'!C16 -> 13679 | D12: ='16_DB-SGX_Loading'!D16 -> 0.61 | E12: =D12/(1+(1-0.17)*(F12/G12)) -> 0.40149196 | F12: =H12/J12% -> 38.488129 | G12: =I12/J12% -> 61.511871 | H12: ='16_DB-SGX_Loading'!E16 -> 8462 | I12: ='16_DB-SGX_Loading'!F16 -> 13524 | J12: =H12+I12 -> 21986 | K12: ='16_DB-SGX_Loading'!H16 -> 91.33 | L12: ='16_DB-SGX_Loading'!I16 -> 4.38 | M12: ='16_DB-SGX_Loading'!J16 -> 2.74 | N12: ='16_DB-SGX_Loading'!K16 -> 2.71 | O12: =(M12-N12)/N12*100 -> 1.1070111 | P12: ='16_DB-SGX_Loading'!M16 -> 2133 | Q12: ='16_DB-SGX_Loading'!N16 -> 735 | R12: ='16_DB-SGX_Loading'!O16 -> 24211 | S12: ='16_DB-SGX_Loading'!P16 -> 479 | T12: =C12/P12 -> 6.4130333 | U12: =C12/Q12 -> 18.610884 | V12: =C12/R12 -> 0.56499112 | W12: =C12/S12 -> 28.557411 | X12: ='16_DB-SGX_Loading'!W16 -> 9CI
A13: 8 | B13: ='16_DB-SGX_Loading'!B17 -> ComfortDelGro | C13: ='16_DB-SGX_Loading'!C17 -> 3120 | D13: ='16_DB-SGX_Loading'!D17 -> 0.24 | E13: =D13/(1+(1-0.17)*(F13/G13)) -> 0.15923447 | F13: =H13/J13% -> 37.930532 | G13: =I13/J13% -> 62.069468 | H13: ='16_DB-SGX_Loading'!E17 -> 1821.5 | I13: ='16_DB-SGX_Loading'!F17 -> 2980.7 | J13: =H13+I13 -> 4802.2 | K13: ='16_DB-SGX_Loading'!H17 -> 13.09 | L13: ='16_DB-SGX_Loading'!I17 -> 5.9 | M13: ='16_DB-SGX_Loading'!J17 -> 1.44 | N13: ='16_DB-SGX_Loading'!K17 -> 1.48 | O13: =(M13-N13)/N13*100 -> -2.7027027 | P13: ='16_DB-SGX_Loading'!M17 -> 5058 | Q13: ='16_DB-SGX_Loading'!N17 -> 793.8 | R13: ='16_DB-SGX_Loading'!O17 -> 6138.9 | S13: ='16_DB-SGX_Loading'!P17 -> -136.5 | T13: =C13/P13 -> 0.6168446 | U13: =C13/Q13 -> 3.9304611 | V13: =C13/R13 -> 0.50823437 | W13: =C13/S13 -> -22.857143 | X13: ='16_DB-SGX_Loading'!W17 -> C52
A14: 9 | B14: ='16_DB-SGX_Loading'!B18 -> Frasers Property | C14: ='16_DB-SGX_Loading'!C18 -> 3808 | D14: ='16_DB-SGX_Loading'!D18 -> 0.33 | E14: =D14/(1+(1-0.17)*(F14/G14)) -> 0.17398972 | F14: =H14/J14% -> 51.930422 | G14: =I14/J14% -> 48.069578 | H14: ='16_DB-SGX_Loading'!E18 -> 18525.843 | I14: ='16_DB-SGX_Loading'!F18 -> 17148.512 | J14: =H14+I14 -> 35674.355 | K14: ='16_DB-SGX_Loading'!H18 -> 16.17 | L14: ='16_DB-SGX_Loading'!I18 -> 4.64 | M14: ='16_DB-SGX_Loading'!J18 -> 0.97 | N14: ='16_DB-SGX_Loading'!K18 -> 1.13 | O14: =(M14-N14)/N14*100 -> -14.159292 | P14: ='16_DB-SGX_Loading'!M18 -> 3403.519 | Q14: ='16_DB-SGX_Loading'!N18 -> 1322.534 | R14: ='16_DB-SGX_Loading'!O18 -> 39747.618 | S14: ='16_DB-SGX_Loading'!P18 -> 981.788 | T14: =C14/P14 -> 1.118842 | U14: =C14/Q14 -> 2.8793211 | V14: =C14/R14 -> 0.095804483 | W14: =C14/S14 -> 3.8786378 | X14: ='16_DB-SGX_Loading'!W18 -> TQ5
B16: Total: | D16: =SUM(D6:D14) -> 3.67 | E16: =SUM(E6:E14) -> 2.6689247 | F16: =AVERAGE(H6:H14)/AVERAGE(I6:I14) -> 0.76199236 | G16: Average D/Average L
B17: Average: | D17: =AVERAGE(D6:D14) -> 0.40777778 | E17: =AVERAGE(E6:E14) -> 0.29654719 | F17: =E17*(1+(1-D50)*F16) -> 0.48409955 | G17: rel-levered beta using the industry component stocks D/L
B18: *Where T is the corporate tax rate of 17%
A20: b | B20: Small and Micro Cap Stocks
B21: Data/Information from SGX or Yahoo Finance website
C22: Total Mkt Cap $ million | D22: LB | E22: UB = LB / (1+ (1-T)* (D/E)) | F22: D %age of debts [Total Debt / (Total Equity + Total Debt)] | G22: E %age of equity [Total Equity / (Total Equity + Total Debt)] | H22: Total debt | I22: Total Equity | J22: Total Equity + Total Debts | K22: P/E ratio | L22: Dividend yield | M22: Sh price on 3 Apr 2026 | N22: Sh price on 31 Dec 2025 | O22: Percentage +ve drop/-ve increase | P22: Gross Revenue ($million) | Q22: EBITDA | R22: Total Assets | S22: Free Cash Flow (FCF) | T22: Price/Gross Revenue | U22: Price/EBITDA | V22: Price/Total Assests | W22: Price/FCF | X22: Stk code | Y22: Currency
A23: 1 | B23: ='16_DB-SGX_Loading'!B22 -> Audience | C23: ='16_DB-SGX_Loading'!C22 -> 60.492 | D23: ='16_DB-SGX_Loading'!D22 -> 0.08 | E23: =D23/(1+(1-$C$55)*(F23/G23)) -> 0.079920179 | F23: =H23/J23% -> 0.12018715 | G23: =I23/J23% -> 99.879813 | H23: ='16_DB-SGX_Loading'!E22 -> 0.028 | I23: ='16_DB-SGX_Loading'!F22 -> 23.269 | J23: =H23+I23 -> 23.297 | K23: ='16_DB-SGX_Loading'!H22 -> 13 | L23: ='16_DB-SGX_Loading'!I22 -> 5.77 | M23: ='16_DB-SGX_Loading'!J22 -> 0.26 | N23: ='16_DB-SGX_Loading'!K22 -> 0.26 | O23: =(N23-M23)/N23*100 -> 0 | P23: ='16_DB-SGX_Loading'!M22 -> 15.956 | Q23: ='16_DB-SGX_Loading'!N22 -> 5.788 | R23: ='16_DB-SGX_Loading'!O22 -> 26.015 | S23: ='16_DB-SGX_Loading'!P22 -> 4.436 | T23: ='16_DB-SGX_Loading'!Q22 -> 3.7911757 | U23: ='16_DB-SGX_Loading'!R22 -> 10.451279 | V23: ='16_DB-SGX_Loading'!S22 -> 2.3252739 | W23: ='16_DB-SGX_Loading'!T22 -> 13.63661 | X23: 1AZ
A24: 2 | B24: ='16_DB-SGX_Loading'!B23 -> Dezign Format | C24: ='16_DB-SGX_Loading'!C23 -> 38 | D24: ='16_DB-SGX_Loading'!D23 -> 1 | E24: =D24/(1+(1-$C$55)*(F24/G24)) -> 0.84807461 | F24: =H24/J24% -> 17.751875 | G24: =I24/J24% -> 82.248125 | H24: ='16_DB-SGX_Loading'!E23 -> 2.391 | I24: ='16_DB-SGX_Loading'!F23 -> 11.078 | J24: =H24+I24 -> 13.469 | K24: ='16_DB-SGX_Loading'!H23 -> 19 | L24: ='16_DB-SGX_Loading'!I23 -> 0 | M24: ='16_DB-SGX_Loading'!J23 -> 0.19 | N24: ='16_DB-SGX_Loading'!K23 -> 0.23 | O24: =(N24-M24)/N24*100 -> 17.391304 | P24: ='16_DB-SGX_Loading'!M23 -> 33.104 | Q24: ='16_DB-SGX_Loading'!N23 -> 3.03 | R24: ='16_DB-SGX_Loading'!O23 -> 24.951 | S24: ='16_DB-SGX_Loading'!P23 -> -6.511 | T24: ='16_DB-SGX_Loading'!Q23 -> 1.1478975 | U24: ='16_DB-SGX_Loading'!R23 -> 12.541254 | V24: ='16_DB-SGX_Loading'!S23 -> 1.5229851 | W24: ='16_DB-SGX_Loading'!T23 -> -5.8362771 | X24: UZF
A25: 3 | B25: ='16_DB-SGX_Loading'!B24 -> GKE | C25: ='16_DB-SGX_Loading'!C24 -> 64.395 | D25: ='16_DB-SGX_Loading'!D24 -> 0.28 | E25: =D25/(1+(1-$C$55)*(F25/G25)) -> 0.1943974 | F25: =H25/J25% -> 34.663595 | G25: =I25/J25% -> 65.336405 | H25: ='16_DB-SGX_Loading'!E24 -> 53.123 | I25: ='16_DB-SGX_Loading'!F24 -> 100.13 | J25: =H25+I25 -> 153.253 | K25: ='16_DB-SGX_Loading'!H24 -> 7.5 | L25: ='16_DB-SGX_Loading'!I24 -> 5.33 | M25: ='16_DB-SGX_Loading'!J24 -> 0.075 | N25: ='16_DB-SGX_Loading'!K24 -> 0.095 | O25: =(N25-M25)/N25*100 -> 21.052632 | P25: ='16_DB-SGX_Loading'!M24 -> 126.519 | Q25: ='16_DB-SGX_Loading'!N24 -> 29.927 | R25: ='16_DB-SGX_Loading'!O24 -> 184.24 | S25: ='16_DB-SGX_Loading'!P24 -> 14.761 | T25: ='16_DB-SGX_Loading'!Q24 -> 0.50897494 | U25: ='16_DB-SGX_Loading'!R24 -> 2.1517359 | V25: ='16_DB-SGX_Loading'!S24 -> 0.34951693 | W25: ='16_DB-SGX_Loading'!T24 -> 4.3625093 | X25: 595 | Y25: JPY
A26: 4 | B26: ='16_DB-SGX_Loading'!B25 -> Hiap Tong | C26: ='16_DB-SGX_Loading'!C25 -> 35.545 | D26: ='16_DB-SGX_Loading'!D25 -> -0.04 | E26: =D26/(1+(1-$C$55)*(F26/G26)) -> -0.027828632 | F26: =H26/J26% -> 34.509974 | G26: =I26/J26% -> 65.490026 | H26: ='16_DB-SGX_Loading'!E25 -> 52.646 | I26: ='16_DB-SGX_Loading'!F25 -> 99.907 | J26: =H26+I26 -> 152.553 | K26: ='16_DB-SGX_Loading'!H25 -> 11.2 | L26: ='16_DB-SGX_Loading'!I25 -> 0.89 | M26: ='16_DB-SGX_Loading'!J25 -> 0.112 | N26: ='16_DB-SGX_Loading'!K25 -> 0.096 | O26: =(N26-M26)/N26*100 -> -16.666667 | P26: ='16_DB-SGX_Loading'!M25 -> 91.916 | Q26: ='16_DB-SGX_Loading'!N25 -> 23.985 | R26: ='16_DB-SGX_Loading'!O25 -> 182.026 | S26: ='16_DB-SGX_Loading'!P25 -> 19.872 | T26: ='16_DB-SGX_Loading'!Q25 -> 0.38671178 | U26: ='16_DB-SGX_Loading'!R25 -> 1.4819679 | V26: ='16_DB-SGX_Loading'!S25 -> 0.1952743 | W26: ='16_DB-SGX_Loading'!T25 -> 1.7886977 | X26: 5PO
A27: 5 | B27: ='16_DB-SGX_Loading'!B26 -> LS 2 Holdings | C27: ='16_DB-SGX_Loading'!C26 -> 14.8 | D27: ='16_DB-SGX_Loading'!D26 -> 4.11 | E27: =D27/(1+(1-$C$55)*(F27/G27)) -> 3.7729933 | F27: =H27/J27% -> 9.7159543 | G27: =I27/J27% -> 90.284046 | H27: ='16_DB-SGX_Loading'!E26 -> 2.562 | I27: ='16_DB-SGX_Loading'!F26 -> 23.807 | J27: =H27+I27 -> 26.369 | K27: ='16_DB-SGX_Loading'!H26 -> 4 | L27: ='16_DB-SGX_Loading'!I26 -> 0 | M27: ='16_DB-SGX_Loading'!J26 -> 0.08 | N27: ='16_DB-SGX_Loading'!K26 -> 0.074 | O27: =(N27-M27)/N27*100 -> -8.1081081 | P27: ='16_DB-SGX_Loading'!M26 -> 71.805 | Q27: ='16_DB-SGX_Loading'!N26 -> 7.614 | R27: ='16_DB-SGX_Loading'!O26 -> 37.841 | S27: ='16_DB-SGX_Loading'!P26 -> 6.154 | T27: ='16_DB-SGX_Loading'!Q26 -> 0.20611378 | U27: ='16_DB-SGX_Loading'!R26 -> 1.9437878 | V27: ='16_DB-SGX_Loading'!S26 -> 0.39111017 | W27: ='16_DB-SGX_Loading'!T26 -> 2.4049399 | X27: ENV
A28: 6 | B28: ='16_DB-SGX_Loading'!B27 -> VCPlus | C28: ='16_DB-SGX_Loading'!C27 -> 17.012 | D28: ='16_DB-SGX_Loading'!D27 -> 0.69 | E28: =D28/(1+(1-$C$55)*(F28/G28)) -> 0.56308174 | F28: =H28/J28% -> 21.356784 | G28: =I28/J28% -> 78.643216 | H28: ='16_DB-SGX_Loading'!E27 -> 0.17 | I28: ='16_DB-SGX_Loading'!F27 -> 0.626 | J28: =H28+I28 -> 0.796 | K28: ='16_DB-SGX_Loading'!H27 -> 0 | L28: ='16_DB-SGX_Loading'!I27 -> 0 | M28: ='16_DB-SGX_Loading'!J27 -> 0.003 | N28: ='16_DB-SGX_Loading'!K27 -> 0.003 | O28: =(N28-M28)/N28*100 -> 0 | P28: ='16_DB-SGX_Loading'!M27 -> 0.191 | Q28: ='16_DB-SGX_Loading'!N27 -> -2.281 | R28: ='16_DB-SGX_Loading'!O27 -> 1.471 | S28: ='16_DB-SGX_Loading'!P27 -> -1.388 | T28: ='16_DB-SGX_Loading'!Q27 -> 89.068063 | U28: ='16_DB-SGX_Loading'!R27 -> -7.4581324 | V28: ='16_DB-SGX_Loading'!S27 -> 11.564922 | W28: ='16_DB-SGX_Loading'!T27 -> -12.256484 | X28: 43E
A29: 7 | B29: ='16_DB-SGX_Loading'!B28 -> ZICO Hldgs | C29: ='16_DB-SGX_Loading'!C28 -> 19.707 | D29: ='16_DB-SGX_Loading'!D28 -> 0.18 | E29: =D29/(1+(1-$C$55)*(F29/G29)) -> 0.142867 | F29: =H29/J29% -> 23.847139 | G29: =I29/J29% -> 76.152861 | H29: ='16_DB-SGX_Loading'!E28 -> 8.936 | I29: ='16_DB-SGX_Loading'!F28 -> 28.536 | J29: =H29+I29 -> 37.472 | K29: ='16_DB-SGX_Loading'!H28 -> 0 | L29: ='16_DB-SGX_Loading'!I28 -> 0 | M29: ='16_DB-SGX_Loading'!J28 -> 0.048 | N29: ='16_DB-SGX_Loading'!K28 -> 0.055 | O29: =(M29-N29)/N29*100 -> -12.727273 | P29: ='16_DB-SGX_Loading'!M28 -> 14.312 | Q29: ='16_DB-SGX_Loading'!N28 -> 3.549 | R29: ='16_DB-SGX_Loading'!O28 -> 42.196 | S29: ='16_DB-SGX_Loading'!P28 -> -0.504 | T29: ='16_DB-SGX_Loading'!Q28 -> 1.3769564 | U29: ='16_DB-SGX_Loading'!R28 -> 5.5528318 | V29: ='16_DB-SGX_Loading'!S28 -> 0.46703479 | W29: ='16_DB-SGX_Loading'!T28 -> -39.10119 | X29: 40W
A30: 8 | B30: ='16_DB-SGX_Loading'!B29 -> UnUsUaL | C30: ='16_DB-SGX_Loading'!C29 -> 25.553 | D30: ='16_DB-SGX_Loading'!D29 -> -0.38 | E30: =D30/(1+(1-$C$55)*(F30/G30)) -> -0.36048031 | F30: =H30/J30% -> 6.124434 | G30: =I30/J30% -> 93.875566 | H30: ='16_DB-SGX_Loading'!E29 -> 1.826 | I30: ='16_DB-SGX_Loading'!F29 -> 27.989 | J30: =H30+I30 -> 29.815 | K30: ='16_DB-SGX_Loading'!H29 -> 0 | L30: ='16_DB-SGX_Loading'!I29 -> 0 | M30: ='16_DB-SGX_Loading'!J29 -> 0.025 | N30: ='16_DB-SGX_Loading'!K29 -> 0.036 | O30: =(M30-N30)/N30*100 -> -30.555556 | P30: ='16_DB-SGX_Loading'!M29 -> 53.219 | Q30: ='16_DB-SGX_Loading'!N29 -> -18.575 | R30: ='16_DB-SGX_Loading'!O29 -> 37.47 | S30: ='16_DB-SGX_Loading'!P29 -> 4.373 | T30: ='16_DB-SGX_Loading'!Q29 -> 0.48014807 | U30: ='16_DB-SGX_Loading'!R29 -> -1.3756662 | V30: ='16_DB-SGX_Loading'!S29 -> 0.6819589 | W30: ='16_DB-SGX_Loading'!T29 -> 5.843357 | X30: 1D1
A31: 9 | B31: ='16_DB-SGX_Loading'!B30 -> Abundante | C31: ='16_DB-SGX_Loading'!C30 -> 15.26 | D31: ='16_DB-SGX_Loading'!D30 -> 0.3 | E31: =D31/(1+(1-$C$55)*(F31/G31)) -> 0.29999866 | F31: =H31/J31% -> 0.00053647781 | G31: =I31/J31% -> 99.999464 | H31: 0.0001 | I31: ='16_DB-SGX_Loading'!F30 -> 18.64 | J31: =H31+I31 -> 18.6401 | K31: ='16_DB-SGX_Loading'!H30 -> 0 | L31: ='16_DB-SGX_Loading'!I30 -> 0 | M31: ='16_DB-SGX_Loading'!J30 -> 0.15 | N31: ='16_DB-SGX_Loading'!K30 -> 0.16 | O31: =(M31-N31)/N31*100 -> -6.25 | P31: ='16_DB-SGX_Loading'!M30 -> 7.326 | Q31: ='16_DB-SGX_Loading'!N30 -> 0.781 | R31: ='16_DB-SGX_Loading'!O30 -> 19.592 | S31: ='16_DB-SGX_Loading'!P30 -> 0.2511 | T31: ='16_DB-SGX_Loading'!Q30 -> 2.0829921 | U31: ='16_DB-SGX_Loading'!R30 -> 19.539052 | V31: ='16_DB-SGX_Loading'!S30 -> 0.77888934 | W31: ='16_DB-SGX_Loading'!T30 -> 60.772601 | X31: 570
A32: 10 | B32: ='16_DB-SGX_Loading'!B32 -> Chasen | C32: ='16_DB-SGX_Loading'!C32 -> 29.45 | D32: ='16_DB-SGX_Loading'!D32 -> 0.28 | E32: =D32/(1+(1-$C$55)*(F32/G32)) -> 0.13883524 | F32: =H32/J32% -> 55.056886 | G32: =I32/J32% -> 44.943114 | H32: ='16_DB-SGX_Loading'!E32 -> 100.704 | I32: ='16_DB-SGX_Loading'!F32 -> 82.205 | J32: =H32+I32 -> 182.909 | K32: ='16_DB-SGX_Loading'!H32 -> 0 | L32: ='16_DB-SGX_Loading'!I32 -> 0 | M32: ='16_DB-SGX_Loading'!J32 -> 0.077 | N32: ='16_DB-SGX_Loading'!K32 -> 0.087 | O32: =(M32-N32)/N32*100 -> -11.494253 | P32: ='16_DB-SGX_Loading'!M32 -> 116.322 | Q32: ='16_DB-SGX_Loading'!N32 -> 5.151 | R32: ='16_DB-SGX_Loading'!O32 -> 205.471 | S32: ='16_DB-SGX_Loading'!P32 -> -53.247 | T32: ='16_DB-SGX_Loading'!Q32 -> 0.25317653 | U32: ='16_DB-SGX_Loading'!R32 -> 5.7173364 | V32: ='16_DB-SGX_Loading'!S32 -> 0.14332923 | W32: ='16_DB-SGX_Loading'!T32 -> -0.5530828 | X32: 5NV
A33: 11 | B33: ='16_DB-SGX_Loading'!B33 -> Eneco Energy | C33: ='16_DB-SGX_Loading'!C33 -> 34.208 | D33: ='16_DB-SGX_Loading'!D33 -> 0.66 | E33: =D33/(1+(1-$C$55)*(F33/G33)) -> 0.48144479 | F33: =H33/J33% -> 30.883656 | G33: =I33/J33% -> 69.116344 | H33: ='16_DB-SGX_Loading'!E33 -> 9.758 | I33: ='16_DB-SGX_Loading'!F33 -> 21.838 | J33: =H33+I33 -> 31.596 | K33: ='16_DB-SGX_Loading'!H33 -> 0 | L33: ='16_DB-SGX_Loading'!I33 -> 0 | M33: ='16_DB-SGX_Loading'!J33 -> 0.009 | N33: ='16_DB-SGX_Loading'!K33 -> 0.01 | O33: =(M33-N33)/N33*100 -> -10 | P33: ='16_DB-SGX_Loading'!M33 -> 31.302 | Q33: ='16_DB-SGX_Loading'!N33 -> 6.523 | R33: ='16_DB-SGX_Loading'!O33 -> 37.445 | S33: ='16_DB-SGX_Loading'!P33 -> 3.373 | T33: ='16_DB-SGX_Loading'!Q33 -> 1.0928375 | U33: ='16_DB-SGX_Loading'!R33 -> 5.2442128 | V33: ='16_DB-SGX_Loading'!S33 -> 0.91355321 | W33: ='16_DB-SGX_Loading'!T33 -> 10.141714 | X33: R14
A34: 12 | B34: ='16_DB-SGX_Loading'!B34 -> KingsmenCreative | C34: ='16_DB-SGX_Loading'!C34 -> 120.159 | D34: ='16_DB-SGX_Loading'!D34 -> 0.22 | E34: =D34/(1+(1-$C$55)*(F34/G34)) -> 0.19939953 | F34: =H34/J34% -> 11.069445 | G34: =I34/J34% -> 88.930555 | H34: ='16_DB-SGX_Loading'!E34 -> 15.468 | I34: ='16_DB-SGX_Loading'!F34 -> 124.268 | J34: =H34+I34 -> 139.736 | K34: ='16_DB-SGX_Loading'!H34 -> 8.5 | L34: ='16_DB-SGX_Loading'!I34 -> 5.04 | M34: ='16_DB-SGX_Loading'!J34 -> 0.595 | N34: ='16_DB-SGX_Loading'!K34 -> 0.5 | O34: =(M34-N34)/N34*100 -> 19 | P34: ='16_DB-SGX_Loading'!M34 -> 372.544 | Q34: ='16_DB-SGX_Loading'!N34 -> 23.413 | R34: ='16_DB-SGX_Loading'!O34 -> 284.754 | S34: ='16_DB-SGX_Loading'!P34 -> 27.541 | T34: ='16_DB-SGX_Loading'!Q34 -> 0.3225364 | U34: ='16_DB-SGX_Loading'!R34 -> 5.1321488 | V34: ='16_DB-SGX_Loading'!S34 -> 0.42197476 | W34: ='16_DB-SGX_Loading'!T34 -> 4.3629135 | X34: 5MZ
A35: 13 | B35: ='16_DB-SGX_Loading'!B19 -> Raffles Edu | C35: ='16_DB-SGX_Loading'!C19 -> 224.357 | D35: ='16_DB-SGX_Loading'!D19 -> 0.72 | E35: =D35/(1+(1-0.17)*(F35/G35)) -> 0.56091346 | F35: =H35/J35% -> 25.468324 | G35: =I35/J35% -> 74.531676 | H35: ='16_DB-SGX_Loading'!E19 -> 218.887 | I35: ='16_DB-SGX_Loading'!F19 -> 640.561 | J35: =H35+I35 -> 859.448 | K35: ='16_DB-SGX_Loading'!H19 -> 0 | L35: ='16_DB-SGX_Loading'!I19 -> 0 | M35: ='16_DB-SGX_Loading'!J19 -> 0.126 | N35: ='16_DB-SGX_Loading'!K19 -> 0.139 | O35: =(M35-N35)/N35*100 -> -9.352518 | P35: ='16_DB-SGX_Loading'!M19 -> 111.71 | Q35: ='16_DB-SGX_Loading'!N19 -> 43.6 | R35: ='16_DB-SGX_Loading'!O19 -> 1018.751 | S35: ='16_DB-SGX_Loading'!P19 -> 0.145 | T35: =C35/P35 -> 2.0083878 | U35: =C35/Q35 -> 5.1458028 | V35: =C35/R35 -> 0.22022751 | W35: =C35/S35 -> 1547.2897 | X35: NR7
B37: Total: | D37: =SUM(D23:D35) -> 8.1 | E37: =SUM(E23:E35) -> 6.8936169 | F37: =AVERAGE(H23:H35)/AVERAGE(I23:I35) -> 0.38782687 | G37: average D/L | S37: total | T37: =SUM(T23:T26)+SUM(T48:T50) -> 5.83476 | U37: =SUM(U23:U26)+SUM(U48:U50) -> 26.626236 | V37: =SUM(V23:V26)+SUM(V48:V50) -> 4.3930502 | W37: =SUM(W23:W26)+SUM(W48:W50) -> 13.951539
B38: Average: | D38: =AVERAGE(D23:D35) -> 0.62307692 | E38: =AVERAGE(E23:E35) -> 0.53027823 | F38: =E38*(1+(1-D50)*F37) -> 0.70097283 | G38: Re-levered beta of small cap components average D/L | S38: average | T38: =T37/11 -> 0.53043273 | U38: =U37/11 -> 2.4205669 | V38: =V37/11 -> 0.3993682 | W38: =W37/11 -> 1.2683218
B39: *Where T is the corporate tax rate of 17% | S39: median | T39: =MEDIAN(T23:T26) -> 0.82843624 | U39: =MEDIAN(U23:U26) -> 6.3015072 | V39: =MEDIAN(V23:V26) -> 0.93625099 | W39: =MEDIAN(W23:W26) -> 3.0756035
B41: Total Industry + Small Cap | D41: =D37+D16 -> 11.77 | E41: =E37+E16 -> 9.5625417 | F41: =(AVERAGE(H6:H14)+AVERAGE(H23:H35))/(AVERAGE(I6:I14)+AVERAGE(I23:I35)) -> 0.75683008 | G41: Total average D/L
D42: =AVERAGE(D23:D35)+AVERAGE(D6:D14) -> 1.0308547 | E42: =AVERAGE(E23:E35)+AVERAGE(E6:E14) -> 0.82682542 | F42: =E42*(1+(1-D50)*F41) -> 1.3462115 | G42: Total re-levered beta
A43: c | B43: Industry premium = (1.346 X 4.65)-4.65 | C43: =(D47*C56)-C56 -> 1.6098834
A45: d | B45: Re-Levered Beta for subject company:
B46: where:
...

Sheet 03b_Size Premium Method 15Y
A1: B. Portfolio (Decile) Returns
A2: Stocks | B2: 1 | C2: 2 | D2: 3 | E2: 4 | F2: 5 | G2: 6 | H2: 7 | I2: 8 | J2: 9 | K2: 10 | L2: 11 | M2: 12 | N2: 13
A3: Year | B3: =B51 -> Audience | C3: =B70 -> Dezign Format | D3: =B89 -> GKE | E3: =B108 -> Hiap Tong | F3: =B127 -> LS 2 Holdings | G3: =I51 -> VCPlus | H3: =I70 -> ZICO Hldgs | I3: =I89 -> UnUsUaL | J3: =I108 -> Abundante | K3: =I127 -> Chasen | L3: =P51 -> Eneco Energy | M3: =P70 -> KingsmenCreative | N3: =P89 -> Raffles Edu | O3: Portfolio Average
A4: 2010 | B4: =E53 -> #DIV/0! | C4: =E72 -> 0 | D4: =E91 -> 0 | E4: =E110 -> 0 | F4: =E129 -> #DIV/0! | G4: =L53 -> #DIV/0! | H4: =L72 -> 0 | I4: =L91 -> 0 | J4: =L110 -> 0.11764706 | K4: =L129 -> 0.15435095 | L4: =S53 -> -0.2531191 | M4: =S72 -> 0.052631579 | N4: =S91 -> -0.23751422 | O4: =AVERAGE(E4+H4+J4+K4+L4+M4+N4) -> -0.16600373
A5: 2011 | B5: =E54 -> #DIV/0! | C5: =E73 -> 0 | D5: =E92 -> 0 | E5: =E111 -> -0.54 | F5: =E130 -> #DIV/0! | G5: =L54 -> #DIV/0! | H5: =L73 -> 0 | I5: =L92 -> 0 | J5: =L111 -> -0.028571429 | K5: =L130 -> -0.39453188 | L5: =S54 -> 0.21415992 | M5: =S73 -> 0.079646018 | N5: =S92 -> -0.48189043 | O5: =AVERAGE(E5+H5+J5+K5+L5+M5+N5) -> -1.1511878
A6: 2012 | B6: =E55 -> #DIV/0! | C6: =E74 -> 0 | D6: =E93 -> 0 | E6: =E112 -> 1.2463768 | F6: =E131 -> #DIV/0! | G6: =L55 -> #DIV/0! | H6: =L74 -> 0 | I6: =L93 -> 0 | J6: =L112 -> -0.015873016 | K6: =L131 -> 0.12103364 | L6: =S55 -> 0.74064404 | M6: =S74 -> 0.42105263 | N6: =S93 -> -0.13180363 | O6: =AVERAGE(E6+H6+J6+K6+L6+M6+N6) -> 2.3814305
A7: 2013 | B7: =E56 -> #DIV/0! | C7: =E75 -> 0 | D7: =E94 -> -0.1778697 | E7: =E113 -> 0.02 | F7: =E132 -> #DIV/0! | G7: =L56 -> #DIV/0! | H7: =L75 -> 0 | I7: =L94 -> 0 | J7: =L113 -> 0.32758621 | K7: =L132 -> -0.27248885 | L7: =S56 -> -0.066666667 | M7: =S75 -> 0.24675325 | N7: =S94 -> -0.23601721 | O7: =AVERAGE(E7+H7+J7+K7+L7+M7+N7) -> 0.019166728
A8: 2014 | B8: =E57 -> #DIV/0! | C8: =E76 -> #DIV/0! | D8: =E95 -> 0.023285899 | E8: =E114 -> 0.061643836 | F8: =E133 -> #DIV/0! | G8: =L57 -> #DIV/0! | H8: =L76 -> 0.17073171 | I8: =L95 -> 0 | J8: =L114 -> 0.26388889 | K8: =L133 -> -0.15971464 | L8: =S57 -> -0.49107143 | M8: =S76 -> 0.086956522 | N8: =S95 -> 0.23627514 | O8: =AVERAGE(E8+H8+J8+K8+L8+M8+N8) -> 0.16871003
A9: 2015 | B9: =E58 -> #DIV/0! | C9: =E77 -> #DIV/0! | D9: =E96 -> -0.11183355 | E9: =E115 -> -0.47741935 | F9: =E134 -> #DIV/0! | G9: =L58 -> #DIV/0! | H9: =L77 -> -0.32291667 | I9: =L96 -> 0 | J9: =L115 -> 0.37647059 | K9: =L134 -> -0.7475539 | L9: =S58 -> -0.50877193 | M9: =S77 -> -0.29166667 | N9: =S96 -> -0.24258129 | O9: =AVERAGE(E9+H9+J9+K9+L9+M9+N9) -> -2.2144392
A10: 2016 | B10: =E59 -> #DIV/0! | C10: =E78 -> #DIV/0! | D10: =E97 -> 0.13161876 | E10: =E116 -> -0.037037037 | F10: =E135 -> #DIV/0! | G10: =L59 -> -0.16935484 | H10: =L78 -> -0.10769231 | I10: =L97 -> 0 | J10: =L116 -> 0.25688073 | K10: =L135 -> -0.075757576 | L10: =S59 -> 0.12857143 | M10: =S78 -> -0.023255814 | N10: =S97 -> -0.19594283 | O10: =AVERAGE(E10+H10+J10+K10+L10+M10+N10) -> -0.054233403
A11: 2017 | B11: =E60 -> #DIV/0! | C11: =E79 -> #DIV/0! | D11: =E98 -> 0.20523416 | E11: =E117 -> 0.53846154 | F11: =E136 -> #DIV/0! | G11: =L60 -> -0.5631068 | H11: =L79 -> -0.15517241 | I11: =L98 -> 0.53250253 | J11: =L117 -> -0.25384615 | K11: =L136 -> 1.6666667 | L11: =S60 -> -0.46202532 | M11: =S79 -> 0.040983607 | N11: =S98 -> 0.37327982 | O11: =AVERAGE(E11+H11+J11+K11+L11+M11+N11) -> 1.7483477
